Workbook

Sheet Grammar
A1: Reference: https://cvc.cervantes.es/ensenanza/biblioteca_ele/plan_curricular/niveles/02_gramatica_inventario_a1-a2.htm
A2: To check the glossary of the terms below: https://cvc.cervantes.es/ensenanza/biblioteca_ele/plan_curricular/niveles/02_gramatica_glosario.htm
A3: Section | B3: Subsection / Item | C3: Topic | D3: Example / Notes | E3: block 1 | F3: Block 2 | G3: block 3
A4: El sustantivo | B4: 1.1.1. Nombres propios | C4: Antropónimos – nombres de pila sin artículo | D4: María, Antonio | E4: =IFERROR(__xludf.DUMMYFUNCTION("IF( C4="""","""", N( ISNUMBER( MATCH( TRIM(SUBSTITUTE(SUBSTITUTE(SUBSTITUTE(SUBSTITUTE(SUBSTITUTE(TO_TEXT(C4),CHAR(160),"" ""),CHAR(8239),"" ""),CHAR(8203),""""),""–"",""-""),""—"",""-"")), ARRAYFORMULA( TRIM( "&" SUBSTITUTE( SUBSTITUTE( SUBSTITUTE( SUBSTITUTE( SUBSTITUTE(SPLIT(TO_TEXT(template!A11),CHAR(10)),CHAR(160),"" ""), CHAR(8239),"" "" ), "&" CHAR(8203),"""" ), ""–"",""-"" ), ""—"",""-"" ) ) ), 0 ) ) ) ) "),0.0) -> 0
A5: El sustantivo | B5: 1.1.1. Nombres propios | C5: Antropónimos – hipocorísticos y diminutivos | D5: Pepe (José), Paco (Francisco), Chelo (Consuelo), Lola (Dolores) | E5: =IFERROR(__xludf.DUMMYFUNCTION("IF( C5="""","""", COUNTIF( ARRAYFORMULA( TRIM( SUBSTITUTE( SUBSTITUTE( SUBSTITUTE( SUBSTITUTE( SUBSTITUTE( SPLIT( FLATTEN( SUBSTITUTE(template!A12:A101, CHAR(10), "&"""|"") ), ""|"" ), CHAR(160),"" "" ), CHAR(8239),"" "" ), CHAR(8203),"""" ), CHAR(8211),""-"" ), CHAR(8212),""-"" ) ) "&" ), TRIM( SUBSTITUTE( SUBSTITUTE( SUBSTITUTE( SUBSTITUTE( SUBSTITUTE( TO_TEXT(C5), CHAR(160),"" "" ), CHAR(8239),"" "" ), CHAR(8203),"""" ), "&"CHAR(8211),""-"" ), CHAR(8212),""-"" ) ) ) ) "),0.0) -> 0
A6: El sustantivo | B6: 1.1.1. Nombres propios | C6: Antropónimos – hipocorísticos hispanoamericanos | D6: Chayo (Rosario), Chava (Isabel), Güicho (Luis), Pancho (Francisco) | E6: =IFERROR(__xludf.DUMMYFUNCTION("IF( C6="""","""", COUNTIF( ARRAYFORMULA( TRIM( SUBSTITUTE( SUBSTITUTE( SUBSTITUTE( SUBSTITUTE( SUBSTITUTE( SPLIT( FLATTEN( SUBSTITUTE(template!A13:A102, CHAR(10), "&"""|"") ), ""|"" ), CHAR(160),"" "" ), CHAR(8239),"" "" ), CHAR(8203),"""" ), CHAR(8211),""-"" ), CHAR(8212),""-"" ) ) "&" ), TRIM( SUBSTITUTE( SUBSTITUTE( SUBSTITUTE( SUBSTITUTE( SUBSTITUTE( TO_TEXT(C6), CHAR(160),"" "" ), CHAR(8239),"" "" ), CHAR(8203),"""" ), "&"CHAR(8211),""-"" ), CHAR(8212),""-"" ) ) ) ) "),0.0) -> 0
A7: El sustantivo | B7: 1.1.1. Nombres propios | C7: Apellidos sin artículo | D7: Fernández, González | E7: =IFERROR(__xludf.DUMMYFUNCTION("IF( C7="""","""", COUNTIF( ARRAYFORMULA( TRIM( SUBSTITUTE( SUBSTITUTE( SUBSTITUTE( SUBSTITUTE( SUBSTITUTE( SPLIT( FLATTEN( SUBSTITUTE(template!A14:A103, CHAR(10), "&"""|"") ), ""|"" ), CHAR(160),"" "" ), CHAR(8239),"" "" ), CHAR(8203),"""" ), CHAR(8211),""-"" ), CHAR(8212),""-"" ) ) "&" ), TRIM( SUBSTITUTE( SUBSTITUTE( SUBSTITUTE( SUBSTITUTE( SUBSTITUTE( TO_TEXT(C7), CHAR(160),"" "" ), CHAR(8239),"" "" ), CHAR(8203),"""" ), "&"CHAR(8211),""-"" ), CHAR(8212),""-"" ) ) ) ) "),0.0) -> 0
A8: El sustantivo | B8: 1.1.1. Nombres propios | C8: Formas de tratamiento | D8: el Sr. Fernández, (Don) Fernando | E8: =IFERROR(__xludf.DUMMYFUNCTION("IF( C8="""","""", COUNTIF( ARRAYFORMULA( TRIM( SUBSTITUTE( SUBSTITUTE( SUBSTITUTE( SUBSTITUTE( SUBSTITUTE( SPLIT( FLATTEN( SUBSTITUTE(template!A15:A104, CHAR(10), "&"""|"") ), ""|"" ), CHAR(160),"" "" ), CHAR(8239),"" "" ), CHAR(8203),"""" ), CHAR(8211),""-"" ), CHAR(8212),""-"" ) ) "&" ), TRIM( SUBSTITUTE( SUBSTITUTE( SUBSTITUTE( SUBSTITUTE( SUBSTITUTE( TO_TEXT(C8), CHAR(160),"" "" ), CHAR(8239),"" "" ), CHAR(8203),"""" ), "&"CHAR(8211),""-"" ), CHAR(8212),""-"" ) ) ) ) "),0.0) -> 0
A9: El sustantivo | B9: 1.1.1. Nombres propios | C9: Formas de tratamiento en Ecuador y Colombia | D9: Don/Doña + nombre o apellido sin connotación despectiva; uso exclusivo en ciertos estratos sociales | E9: =IFERROR(__xludf.DUMMYFUNCTION("IF( C9="""","""", COUNTIF( ARRAYFORMULA( TRIM( SUBSTITUTE( SUBSTITUTE( SUBSTITUTE( SUBSTITUTE( SUBSTITUTE( SPLIT( FLATTEN( SUBSTITUTE(template!A16:A105, CHAR(10), "&"""|"") ), ""|"" ), CHAR(160),"" "" ), CHAR(8239),"" "" ), CHAR(8203),"""" ), CHAR(8211),""-"" ), CHAR(8212),""-"" ) ) "&" ), TRIM( SUBSTITUTE( SUBSTITUTE( SUBSTITUTE( SUBSTITUTE( SUBSTITUTE( TO_TEXT(C9), CHAR(160),"" "" ), CHAR(8239),"" "" ), CHAR(8203),"""" ), "&"CHAR(8211),""-"" ), CHAR(8212),""-"" ) ) ) ) "),0.0) -> 0
A10: El sustantivo | B10: 1.1.1. Nombres propios | C10: Formas de tratamiento en República Dominicana | D10: Su merced | E10: =IFERROR(__xludf.DUMMYFUNCTION("IF( C10="""","""", COUNTIF( ARRAYFORMULA( TRIM( SUBSTITUTE( SUBSTITUTE( SUBSTITUTE( SUBSTITUTE( SUBSTITUTE( SPLIT( FLATTEN( SUBSTITUTE(template!A17:A106, CHAR(10),"&" ""|"") ), ""|"" ), CHAR(160),"" "" ), CHAR(8239),"" "" ), CHAR(8203),"""" ), CHAR(8211),""-"" ), CHAR(8212),""-"" ) ) "&" ), TRIM( SUBSTITUTE( SUBSTITUTE( SUBSTITUTE( SUBSTITUTE( SUBSTITUTE( TO_TEXT(C10), CHAR(160),"" "" ), CHAR(8239),"" "" ), CHAR(8203),"""" ), "&" CHAR(8211),""-"" ), CHAR(8212),""-"" ) ) ) ) "),0.0) -> 0
A11: El sustantivo | B11: 1.1.1. Nombres propios | C11: Topónimos – países sin artículo | D11: España, Italia | E11: =IFERROR(__xludf.DUMMYFUNCTION("IF( C11="""","""", COUNTIF( ARRAYFORMULA( TRIM( SUBSTITUTE( SUBSTITUTE( SUBSTITUTE( SUBSTITUTE( SUBSTITUTE( SPLIT( FLATTEN( SUBSTITUTE(template!A18:A107, CHAR(10),"&" ""|"") ), ""|"" ), CHAR(160),"" "" ), CHAR(8239),"" "" ), CHAR(8203),"""" ), CHAR(8211),""-"" ), CHAR(8212),""-"" ) ) "&" ), TRIM( SUBSTITUTE( SUBSTITUTE( SUBSTITUTE( SUBSTITUTE( SUBSTITUTE( TO_TEXT(C11), CHAR(160),"" "" ), CHAR(8239),"" "" ), CHAR(8203),"""" ), "&" CHAR(8211),""-"" ), CHAR(8212),""-"" ) ) ) ) "),0.0) -> 0
A12: El sustantivo | B12: 1.1.1. Nombres propios | C12: Topónimos – excepción | D12: El Salvador | E12: =IFERROR(__xludf.DUMMYFUNCTION("IF( C12="""","""", COUNTIF( ARRAYFORMULA( TRIM( SUBSTITUTE( SUBSTITUTE( SUBSTITUTE( SUBSTITUTE( SUBSTITUTE( SPLIT( FLATTEN( SUBSTITUTE(template!A19:A108, CHAR(10),"&" ""|"") ), ""|"" ), CHAR(160),"" "" ), CHAR(8239),"" "" ), CHAR(8203),"""" ), CHAR(8211),""-"" ), CHAR(8212),""-"" ) ) "&" ), TRIM( SUBSTITUTE( SUBSTITUTE( SUBSTITUTE( SUBSTITUTE( SUBSTITUTE( TO_TEXT(C12), CHAR(160),"" "" ), CHAR(8239),"" "" ), CHAR(8203),"""" ), "&" CHAR(8211),""-"" ), CHAR(8212),""-"" ) ) ) ) "),0.0) -> 0
A13: El sustantivo | B13: 1.1.1. Nombres propios | C13: Topónimos – ciudades y localidades | D13: Madrid, París, Alcalá de Henares | E13: =IFERROR(__xludf.DUMMYFUNCTION("IF( C13="""","""", COUNTIF( ARRAYFORMULA( TRIM( SUBSTITUTE( SUBSTITUTE( SUBSTITUTE( SUBSTITUTE( SUBSTITUTE( SPLIT( FLATTEN( SUBSTITUTE(template!A20:A109, CHAR(10),"&" ""|"") ), ""|"" ), CHAR(160),"" "" ), CHAR(8239),"" "" ), CHAR(8203),"""" ), CHAR(8211),""-"" ), CHAR(8212),""-"" ) ) "&" ), TRIM( SUBSTITUTE( SUBSTITUTE( SUBSTITUTE( SUBSTITUTE( SUBSTITUTE( TO_TEXT(C13), CHAR(160),"" "" ), CHAR(8239),"" "" ), CHAR(8203),"""" ), "&" CHAR(8211),""-"" ), CHAR(8212),""-"" ) ) ) ) "),0.0) -> 0
A14: El sustantivo | B14: 1.1.2. Nombres comunes | C14: Nombres de periodos temporales | D14: mediodía, tarde, noche | E14: =IFERROR(__xludf.DUMMYFUNCTION("IF( C14="""","""", COUNTIF( ARRAYFORMULA( TRIM( SUBSTITUTE( SUBSTITUTE( SUBSTITUTE( SUBSTITUTE( SUBSTITUTE( SPLIT( FLATTEN( SUBSTITUTE(template!A21:A110, CHAR(10),"&" ""|"") ), ""|"" ), CHAR(160),"" "" ), CHAR(8239),"" "" ), CHAR(8203),"""" ), CHAR(8211),""-"" ), CHAR(8212),""-"" ) ) "&" ), TRIM( SUBSTITUTE( SUBSTITUTE( SUBSTITUTE( SUBSTITUTE( SUBSTITUTE( TO_TEXT(C14), CHAR(160),"" "" ), CHAR(8239),"" "" ), CHAR(8203),"""" ), "&" CHAR(8211),""-"" ), CHAR(8212),""-"" ) ) ) ) "),0.0) -> 0
A15: El sustantivo | B15: 1.2. El género de los sustantivos | C15: Masculino en –o y femenino en –a | D15: amigo/amiga, vecino/vecina, libro/casa | E15: =IFERROR(__xludf.DUMMYFUNCTION("IF( C15="""","""", COUNTIF( ARRAYFORMULA( TRIM( SUBSTITUTE( SUBSTITUTE( SUBSTITUTE( SUBSTITUTE( SUBSTITUTE( SPLIT( FLATTEN( SUBSTITUTE(template!A22:A111, CHAR(10),"&" ""|"") ), ""|"" ), CHAR(160),"" "" ), CHAR(8239),"" "" ), CHAR(8203),"""" ), CHAR(8211),""-"" ), CHAR(8212),""-"" ) ) "&" ), TRIM( SUBSTITUTE( SUBSTITUTE( SUBSTITUTE( SUBSTITUTE( SUBSTITUTE( TO_TEXT(C15), CHAR(160),"" "" ), CHAR(8239),"" "" ), CHAR(8203),"""" ), "&" CHAR(8211),""-"" ), CHAR(8212),""-"" ) ) ) ) "),0.0) -> 0
A16: El sustantivo | B16: 1.2. El género de los sustantivos | C16: Masculino/femenino con vocal ≠ o/a | D16: el peine, la muerte | E16: =IFERROR(__xludf.DUMMYFUNCTION("IF( C16="""","""", COUNTIF( ARRAYFORMULA( TRIM( SUBSTITUTE( SUBSTITUTE( SUBSTITUTE( SUBSTITUTE( SUBSTITUTE( SPLIT( FLATTEN( SUBSTITUTE(template!A23:A112, CHAR(10),"&" ""|"") ), ""|"" ), CHAR(160),"" "" ), CHAR(8239),"" "" ), CHAR(8203),"""" ), CHAR(8211),""-"" ), CHAR(8212),""-"" ) ) "&" ), TRIM( SUBSTITUTE( SUBSTITUTE( SUBSTITUTE( SUBSTITUTE( SUBSTITUTE( TO_TEXT(C16), CHAR(160),"" "" ), CHAR(8239),"" "" ), CHAR(8203),"""" ), "&" CHAR(8211),""-"" ), CHAR(8212),""-"" ) ) ) ) "),0.0) -> 0
A17: El sustantivo | B17: 1.2. El género de los sustantivos | C17: Masculino/femenino con consonante | D17: el árbol, la catedral, la solución, el corazón | E17: =IFERROR(__xludf.DUMMYFUNCTION("IF( C17="""","""", COUNTIF( ARRAYFORMULA( TRIM( SUBSTITUTE( SUBSTITUTE( SUBSTITUTE( SUBSTITUTE( SUBSTITUTE( SPLIT( FLATTEN( SUBSTITUTE(template!A24:A113, CHAR(10),"&" ""|"") ), ""|"" ), CHAR(160),"" "" ), CHAR(8239),"" "" ), CHAR(8203),"""" ), CHAR(8211),""-"" ), CHAR(8212),""-"" ) ) "&" ), TRIM( SUBSTITUTE( SUBSTITUTE( SUBSTITUTE( SUBSTITUTE( SUBSTITUTE( TO_TEXT(C17), CHAR(160),"" "" ), CHAR(8239),"" "" ), CHAR(8203),"""" ), "&" CHAR(8211),""-"" ), CHAR(8212),""-"" ) ) ) ) "),0.0) -> 0
A18: El sustantivo | B18: 1.2. El género de los sustantivos | C18: Femenino en –o (abreviación) | D18: la moto (motocicleta), la foto (fotografía), la radio (radiodifusión) | E18: =IFERROR(__xludf.DUMMYFUNCTION("IF( C18="""","""", COUNTIF( ARRAYFORMULA( TRIM( SUBSTITUTE( SUBSTITUTE( SUBSTITUTE( SUBSTITUTE( SUBSTITUTE( SPLIT( FLATTEN( SUBSTITUTE(template!A25:A114, CHAR(10),"&" ""|"") ), ""|"" ), CHAR(160),"" "" ), CHAR(8239),"" "" ), CHAR(8203),"""" ), CHAR(8211),""-"" ), CHAR(8212),""-"" ) ) "&" ), TRIM( SUBSTITUTE( SUBSTITUTE( SUBSTITUTE( SUBSTITUTE( SUBSTITUTE( TO_TEXT(C18), CHAR(160),"" "" ), CHAR(8239),"" "" ), CHAR(8203),"""" ), "&" CHAR(8211),""-"" ), CHAR(8212),""-"" ) ) ) ) "),0.0) -> 0
A19: El sustantivo | B19: 1.2. El género de los sustantivos | C19: Heteronimia | D19: el padre/la madre, el hombre/la mujer | E19: =IFERROR(__xludf.DUMMYFUNCTION("IF( C19="""","""", COUNTIF( ARRAYFORMULA( TRIM( SUBSTITUTE( SUBSTITUTE( SUBSTITUTE( SUBSTITUTE( SUBSTITUTE( SPLIT( FLATTEN( SUBSTITUTE(template!A26:A115, CHAR(10),"&" ""|"") ), ""|"" ), CHAR(160),"" "" ), CHAR(8239),"" "" ), CHAR(8203),"""" ), CHAR(8211),""-"" ), CHAR(8212),""-"" ) ) "&" ), TRIM( SUBSTITUTE( SUBSTITUTE( SUBSTITUTE( SUBSTITUTE( SUBSTITUTE( TO_TEXT(C19), CHAR(160),"" "" ), CHAR(8239),"" "" ), CHAR(8203),"""" ), "&" CHAR(8211),""-"" ), CHAR(8212),""-"" ) ) ) ) "),0.0) -> 0
A20: El sustantivo | B20: 1.3. El número de los sustantivos | C20: Plural terminación en vocal: –s | D20: mesa/mesas, libro/libros | E20: =IFERROR(__xludf.DUMMYFUNCTION("IF( C20="""","""", N( COUNTIF( ARRAYFORMULA( TRIM( SUBSTITUTE( SPLIT( TO_TEXT(template!A27), CHAR(10) ), CHAR(160), "" "" ) ) ), TRIM( SUBSTITUTE( TO_TEXT(C20), CHAR(160), "" "" ) ) )>0 ) ) "),0.0) -> 0
A21: El sustantivo | B21: 1.3. El número de los sustantivos | C21: Plural terminación en consonante: –es | D21: árbol/árboles, pared/paredes, tenedor/tenedores | E21: =IFERROR(__xludf.DUMMYFUNCTION("IF( C21="""","""", N( COUNTIF( ARRAYFORMULA( TRIM( SUBSTITUTE( SPLIT( TO_TEXT(template!A28), CHAR(10) ), CHAR(160), "" "" ) ) ), TRIM( SUBSTITUTE( TO_TEXT(C21), CHAR(160), "" "" ) ) )>0 ) ) "),0.0) -> 0
A22: El sustantivo | B22: 1.3. El número de los sustantivos | C22: Plural terminación en –s monosílabo o aguda | D22: país/países | E22: =IFERROR(__xludf.DUMMYFUNCTION("IF( C22="""","""", N( COUNTIF( ARRAYFORMULA( TRIM( SUBSTITUTE( SPLIT( TO_TEXT(template!A29), CHAR(10) ), CHAR(160), "" "" ) ) ), TRIM( SUBSTITUTE( TO_TEXT(C22), CHAR(160), "" "" ) ) )>0 ) ) "),0.0) -> 0
A23: El sustantivo | B23: 1.3. El número de los sustantivos | C23: Significado del plural – suma de individuos iguales | D23: el coche/los coches | E23: =IFERROR(__xludf.DUMMYFUNCTION("IF( C23="""", """", N( COUNTIF( SPLIT(SUBSTITUIR(template!A30,CHAR(10),"",""),"",""), C23 )>0 ) ) "),0.0) -> 0
A24: El adjetivo | B24: 2.1.1. Adjetivos calificativos | C24: Función de complemento del nombre | D24: el chico guapo | E24: =IFERROR(__xludf.DUMMYFUNCTION("IF( C24="""", """", N( COUNTIF( SPLIT(SUBSTITUIR(template!A31,CHAR(10),"",""),"",""), C24 )>0 ) ) "),0.0) -> 0
A25: El adjetivo | B25: 2.1.1. Adjetivos calificativos | C25: Función de atributo | D25: El chico es guapo | E25: =IFERROR(__xludf.DUMMYFUNCTION("IF( C25="""", """", N( COUNTIF( SPLIT(SUBSTITUIR(template!A32,CHAR(10),"",""),"",""), C25 )>0 ) ) "),0.0) -> 0
A26: El adjetivo | B26: 2.1.1. Adjetivos calificativos | C26: Incompatibilidad con posesivos | D26: ✘ mi guapo | E26: =IFERROR(__xludf.DUMMYFUNCTION("IF( C26="""", """", N( COUNTIF( SPLIT(SUBSTITUIR(template!A33,CHAR(10),"",""),"",""), C26 )>0 ) ) "),0.0) -> 0
A27: El adjetivo | B27: 2.1.2. Adjetivos relacionales | C27: Gentilicios muy frecuentes | D27: español, francés, japonés | E27: =IFERROR(__xludf.DUMMYFUNCTION("IF( C27="""", """", N( COUNTIF( SPLIT(SUBSTITUIR(template!A34,CHAR(10),"",""),"",""), C27 )>0 ) ) "),0.0) -> 0
A28: El adjetivo | B28: 2.2. El género del adjetivo | C28: Masculino en -o / femenino en -a | D28: alto / alta | E28: =IFERROR(__xludf.DUMMYFUNCTION("IF( C28="""", """", N( COUNTIF( SPLIT(SUBSTITUIR(template!A35,CHAR(10),"",""),"",""), C28 )>0 ) ) "),0.0) -> 0
A29: El adjetivo | B29: 2.2. El género del adjetivo | C29: Masculino en consonante / femenino en -a (gentilicios) | D29: español / española, francés / francesa | E29: =IFERROR(__xludf.DUMMYFUNCTION("IF( C29="""", """", N( COUNTIF( SPLIT(SUBSTITUIR(template!A36,CHAR(10),"",""),"",""), C29 )>0 ) ) "),0.0) -> 0
A30: El adjetivo | B30: 2.2. El género del adjetivo | C30: Invariables terminados en consonante | D30: difícil, fácil | E30: =IFERROR(__xludf.DUMMYFUNCTION("IF( C30="""", """", N( COUNTIF( SPLIT(SUBSTITUIR(template!A37,CHAR(10),"",""),"",""), C30 )>0 ) ) "),0.0) -> 0
A31: El adjetivo | B31: 2.2. El género del adjetivo | C31: Gentilicios terminados en -í, -ú | D31: marroquí, hindú | E31: =IFERROR(__xludf.DUMMYFUNCTION("IF( C31="""", """", N( COUNTIF( SPLIT(SUBSTITUIR(template!A38,CHAR(10),"",""),"",""), C31 )>0 ) ) "),0.0) -> 0
A32: El adjetivo | B32: 2.3. El número del adjetivo | C32: Plural terminación en vocal: -s | D32: alto / altos, española / españolas | E32: =IFERROR(__xludf.DUMMYFUNCTION("IF( C32="""", """", N( COUNTIF( SPLIT(SUBSTITUIR(template!A39,CHAR(10),"",""),"",""), C32 )>0 ) ) "),0.0) -> 0
A33: El adjetivo | B33: 2.3. El número del adjetivo | C33: Plural terminación en consonante: -es | D33: fácil / fáciles | E33: =IFERROR(__xludf.DUMMYFUNCTION("IF( C33="""", """", N( COUNTIF( SPLIT(SUBSTITUIR(template!A40,CHAR(10),"",""),"",""), C33 )>0 ) ) "),0.0) -> 0
A34: El adjetivo | B34: 2.4. Posición del adjetivo | C34: Posición postnominal (especificativos) | D34: un chico guapo | E34: =IFERROR(__xludf.DUMMYFUNCTION("IF( C34="""", """", N( COUNTIF( SPLIT(SUBSTITUIR(template!A41,CHAR(10),"",""),"",""), C34 )>0 ) ) "),0.0) -> 0
A35: El adjetivo | B35: 2.5. Grados del adjetivo | C35: Positivo | D35: un chico guapo | E35: =IFERROR(__xludf.DUMMYFUNCTION("IF( C35="""", """", N( COUNTIF( SPLIT(SUBSTITUIR(template!A42,CHAR(10),"",""),"",""), C35 )>0 ) ) "),0.0) -> 0
A36: El adjetivo | B36: 2.5. Grados del adjetivo | C36: Superlativo absoluto con “muy” | D36: muy guapo | E36: =IFERROR(__xludf.DUMMYFUNCTION("IF( C36="""", """", N( COUNTIF( SPLIT(SUBSTITUIR(template!A43,CHAR(10),"",""),"",""), C36 )>0 ) ) "),0.0) -> 0
A37: El artículo | B37: 3.1. El artículo definido | C37: Paradigma regular | D37: el, la, los, las | E37: =IFERROR(__xludf.DUMMYFUNCTION("IF( C37="""", """", N( COUNTIF( SPLIT(SUBSTITUIR(template!A44,CHAR(10),"",""),"",""), C37 )>0 ) ) "),0.0) -> 0
A38: El artículo | B38: 3.1. El artículo definido | C38: Formas contractas | D38: al, del | E38: =IFERROR(__xludf.DUMMYFUNCTION("IF( C38="""", """", N( COUNTIF( SPLIT(SUBSTITUIR(template!A45,CHAR(10),"",""),"",""), C38 )>0 ) ) "),0.0) -> 0
A39: El artículo | B39: 3.1. El artículo definido | C39: Restricciones por tipo de sustantivo | D39: — | E39: =IFERROR(__xludf.DUMMYFUNCTION("IF( C39="""", """", N( COUNTIF( SPLIT(SUBSTITUIR(template!A46,CHAR(10),"",""),"",""), C39 )>0 ) ) "),0.0) -> 0
A40: El artículo | B40: 3.1. El artículo definido | C40: Ausencia con nombre propio de persona (regla general) | D40: — | E40: =IFERROR(__xludf.DUMMYFUNCTION("IF( C40="""", """", N( COUNTIF( SPLIT(SUBSTITUIR(template!A47,CHAR(10),"",""),"",""), C40 )>0 ) ) "),0.0) -> 0
...

Sheet Pronunciation
A1: Reference: https://cvc.cervantes.es/ensenanza/biblioteca_ele/plan_curricular/niveles/03_pronunciacion_inventario_a1-a2.htm
A2: Section | B2: Subsection / Item | C2: Topic | D2: Example / Notes
A3: 1. La base de articulación | B3: 1.1. Caracterización general del español | C3: Modo normal de fonación
A4: 1. La base de articulación | B4: 1.1. Caracterización general del español | C4: Grado de tensión | D4: Menor que francés, superior al inglés
A5: 1. La base de articulación | B5: 1.1. Caracterización general del español | C5: Pureza de las vocales | D5: No hay vocales anteriores redondeadas
A6: 1. La base de articulación | B6: 1.1. Caracterización general del español | C6: Ausencia de africación en las consonantes
A7: 1. La base de articulación | B7: 1.1. Caracterización general del español | C7: Mantenimiento del timbre en vocales inacentuadas
A8: 1. La base de articulación | B8: 1.1. Caracterización general del español | C8: Movimiento de labios | D8: Relativamente marcado
A9: 1. La base de articulación | B9: 1.1. Caracterización general del español | C9: Nasalización | D9: Poco constante, sin relevancia fonológica
A10: 1. La base de articulación | B10: 1.1. Caracterización general del español | C10: Base articulatoria creciente | D10: Tendencia a la sílaba abierta
A11: 1. La base de articulación | B11: 1.1. Caracterización general del español | C11: Base central-anterior | D11: Predominio de alveolares y palatales
A12: 1. La base de articulación | B12: Precisiones sobre «acento idiomático» | C12: Noción del acento | D12: Hábitos articulatorios, procedencia geográfica/sociocultural
A13: 1. La base de articulación | B13: Precisiones sobre «acento idiomático» | C13: Variedades | D13: Información sobre articulación en el mundo hispánico
A14: 2. La entonación | B14: 2.1. Segmentación en unidades melódicas | C14: Correspondencia con puntuación | D14: Punto
A15: 2. La entonación | B15: 2.1. Segmentación en unidades melódicas | C15: Correspondencia con puntuación | D15: Coma
A16: 2. La entonación | B16: 2.1. Segmentación en unidades melódicas | C16: Correspondencia con puntuación | D16: Signos de interrogación y exclamación
A17: 2. La entonación | B17: 2.1. Segmentación en unidades melódicas | C17: Extensión de la unidad | D17: Unidad mínima: palabra monosilábica (¿Quién ha venido? – Yo.)
A18: 2. La entonación | B18: 2.1. Segmentación en unidades melódicas | C18: Extensión de la unidad | D18: Unidades de 5–10 sílabas: predomina 7–8 (Trabaja en un banco.)
A19: 2. La entonación | B19: 2.1. Segmentación en unidades melódicas | C19: Extensión de la unidad | D19: Escasez de <5 y >10–15 sílabas (¿Qué? / No creo que tengas razón…)
... A89: 4. Ritmo, pausas y tiempo | B89: 4.2.3. Pausas llenas | C89: Interjecciones | D89: ¡a:!
A90: 4. Ritmo, pausas y tiempo | B90: 4.2.4. Grupo fónico | C90: Concepto y extensión
A91: 5. Los fonemas | B91: 5.1.1. Vocales | C91: Cualidad /a, e, i, o, u/ | D91: Claridad y precisión
A92: 5. Los fonemas | B92: 5.1.1. Vocales | C92: Comparación | D92: Otras lenguas: francés, inglés, alemán
A93: 5. Los fonemas | B93: 5.1.1. Vocales | C93: Posición de lengua | D93: Vocal a (central), e/i (anteriores), o/u (posteriores)
A94: 5. Los fonemas | B94: 5.1.1. Vocales | C94: Abertura mandibular | D94: a (abierta), e/o (medias), i/u (cerradas)
A95: 5. Los fonemas | B95: 5.1.1. Vocales | C95: Ataque suave | D95: No hay golpe de glotis
A96: 5. Los fonemas | B96: 5.1.2. Comparación de vocales | C96: A | D96: Central (caro, rápido…)
A97: 5. Los fonemas | B97: 5.1.2. Comparación de vocales | C97: I | D97: Similar al francés vie, menos cerrada
A98: 5. Los fonemas | B98: 5.1.2. Comparación de vocales | C98: E | D98: No tan cerrada, no diptongada
A99: 5. Los fonemas | B99: 5.1.2. Comparación de vocales | C99: O | D99: No cerrada, no diptongada como inglés note
A100: 5. Los fonemas | B100: 5.1.2. Comparación de vocales | C100: U | D100: Similar al francés tout
A101: 5. Los fonemas | B101: 5.1.3. Diptongos | C101: Crecientes | D101: fiasco, viejo, labio, guante
A102: 5. Los fonemas | B102: 5.1.3. Diptongos | C102: Decrecientes | D102: bailar, aula, ley, euro
... A125: 5. Los fonemas | B125: 5.3.2. Sirrema | C125: Pronombre átono + verbo | D125: la vi ayer > laviayer

Sheet Ortography
A1: Section | B1: Subsection / Item | C1: Topic | D1: Example / Notes
A2: 1. Ortografía de letras y palabras | B2: 1.1. Abecedario | C2: Nombre de las letras del abecedario o alfabeto
A3: 1. Ortografía de letras y palabras | B3: 1.1. Abecedario | C3: Letras con varios nombres en español | D3: b: be, be alta, be larga
A4: 1. Ortografía de letras y palabras | B4: 1.1. Abecedario | C4: Letras con varios nombres en español | D4: r/rr: ere, erre
A5: 1. Ortografía de letras y palabras | B5: 1.1. Abecedario | C5: Letras con varios nombres en español | D5: v: uve, ve, ve baja, ve corta
A6: 1. Ortografía de letras y palabras | B6: 1.1. Abecedario | C6: Letras con varios nombres en español | D6: w: uve doble, ve doble, doble uve, doble u
A7: 1. Ortografía de letras y palabras | B7: 1.1. Abecedario | C7: Letras con varios nombres en español | D7: y: i griega, ye
A8: 1. Ortografía de letras y palabras | B8: 1.1. Abecedario | C8: Letras con varios nombres en español | D8: z: zeta
A9: 1. Ortografía de letras y palabras | B9: 1.1. Abecedario | C9: Plural de las letras | D9: los eses, los ces – “Esta palabra tiene dos lés”
A10: 1. Ortografía de letras y palabras | B10: 1.1. Abecedario | C10: Correspondencia de más de una letra para un sonido | D10: b/v → /b/
A11: 1. Ortografía de letras y palabras | B11: 1.1. Abecedario | C11: Correspondencia de más de una letra para un sonido | D11: g/e, g/i → /x/
A12: 1. Ortografía de letras y palabras | B12: 1.1. Abecedario | C12: Correspondencia de más de una letra para un sonido | D12: k/qu + e,a,o,u → /k/
A13: 1. Ortografía de letras y palabras | B13: 1.1. Abecedario | C13: Correspondencia de una letra para más de un sonido | D13: v → /u/, /b/
A14: 1. Ortografía de letras y palabras | B14: 1.1. Abecedario | C14: Correspondencia de una letra para más de un sonido | D14: y → /ʝ/, /i/
A15: 1. Ortografía de letras y palabras | B15: 1.1. Abecedario | C15: Dígrafos | D15: ch, ll
A16: 1. Ortografía de letras y palabras | B16: 1.1. Abecedario | C16: Deletreo
A17: 1. Ortografía de letras y palabras | B17: 1.1. Abecedario | C17: Escasa frecuencia de aparición de consonantes idénticas contiguas en español
A18: 1. Ortografía de letras y palabras | B18: 1.2. Vocales | C18: Letras a, e, i, o, u – representación gráfica | D18: /a/, /e/, /i/, /o/, /u/
A19: 1. Ortografía de letras y palabras | B19: 1.2. Vocales | C19: Susceptibles de llevar tilde | D19: (en oposición a las consonantes)
A20: 1. Ortografía de letras y palabras | B20: 1.2. Vocales | C20: Formas contractas | D20: al, del
A21: 1. Ortografía de letras y palabras | B21: 1.2. Vocales | C21: Conjunción e/y | D21: *Hablo español e inglés* / *Hablo español y inglés*
A22: 1. Ortografía de letras y palabras | B22: 1.2. Vocales | C22: Conjunción o/u | D22: *Tiene diez o once libros* / *Tiene diez u once libros*
A23: 1. Ortografía de letras y palabras | B23: 1.3. Consonantes | C23: 1.3.1. Letra b | D23: Representación gráfica del fonema labial sonoro /b/
A24: 1. Ortografía de letras y palabras | B24: 1.3. Consonantes | C24: 1.3.1. Letra v | D24: Representación gráfica del fonema labial sonoro /b/
A25: 1. Ortografía de letras y palabras | B25: 1.3. Consonantes | C25: 1.3.1. Letra v | D25: Presente de indicativo de *ir*
A26: 1. Ortografía de letras y palabras | B26: 1.3. Consonantes | C26: 1.3.1. Letra w | D26: Representación gráfica del fonema semiconsonántico /w/ en voces no adaptadas | E26: sándwich, web
A27: 1. Ortografía de letras y palabras | B27: 1.3. Consonantes | C27: 1.3.2. Letra c | D27: Representación gráfica del fonema oclusivo velar sordo /k/ | E27: ante a, o, u, consonante y en posición final de sílaba (calle, compañero, cuatro, clase, actor)
A28: 1. Ortografía de letras y palabras | B28: 1.3. Consonantes | C28: 1.3.2. Letra c | D28: Representación gráfica del fonema fricativo interdental sordo /θ/ | E28: ante e, i (cena, cine)
A29: 1. Ortografía de letras y palabras | B29: 1.3. Consonantes | C29: 1.3.2. Letra c | D29: Excepción | E29: zeta
A30: 1. Ortografía de letras y palabras | B30: 1.3. Consonantes | C30: 1.3.2. Letra c | D30: Seseo – representación del fonema predorsal fricativo sordo /s/ | E30: (Hispanoamérica, suroeste de España, Canarias)
A31: 1. Ortografía de letras y palabras | B31: 1.3. Consonantes | C31: 1.3.2. Letra c | D31: Posibilidad de duplicación | E31: cc en español (lección, dirección, diccionario)
A32: 1. Ortografía de letras y palabras | B32: 1.3. Consonantes | C32: 1.3.2. Letra k | D32: Representación gráfica del fonema oclusivo velar sordo /k/ | E32: kilómetro
A33: 1. Ortografía de letras y palabras | B33: 1.3. Consonantes | C33: 1.3.2. Letra q | D33: Dígrafo qu ante e,i → /k/ | E33: pequeño, quien
A34: 1. Ortografía de letras y palabras | B34: 1.3. Consonantes | C34: 1.3.2. Letra z | D34: Representación gráfica del fonema fricativo interdental /θ/ | E34: ante a, o, u (zapatos, brazo, azul)
A35: 1. Ortografía de letras y palabras | B35: 1.3. Consonantes | C35: 1.3.2. Letra z | D35: Excepción | E35: zeta
A36: 1. Ortografía de letras y palabras | B36: 1.3. Consonantes | C36: 1.3.2. Letra z | D36: Seseo – /s/ | E36: (Hispanoamérica, suroeste de España, Canarias)
A37: 1. Ortografía de letras y palabras | B37: 1.3. Consonantes | C37: 1.3.2. Letra z | D37: Posición final de sílaba o palabra | E37: mezquita, lápiz
... A42: 1. Ortografía de letras y palabras | B42: 1.3. Consonantes | C42: 1.3.3. Letra j | D42: Representación gráfica del fonema velar sordo /x/ | E42: Juan, extranjero, reloj
A43: 1. Ortografía de letras y palabras | B43: 1.3. Consonantes | C43: 1.3.4. Letra h | D43: Correspondencia de la h con ausencia de sonido
A44: 1. Ortografía de letras y palabras | B44: 1.3. Consonantes | C44: 1.3.4. Letra h | D44: Posición de la letra – inicio de palabra | E44: hermano, hijo
...

Sheet Chapter Status
A1: Due Date | B1: Person/ Status | C1: Type | D1: Name | E1: dashed-name | F1: QA | G1: PR Links/ notes
B2: 0 | C2: Chapter | D2: Welcome to A1 Professional Spanish | E2: es-a1-chapter-welcome-to-a1-professional-spanish | F2: FALSE
A3: 45940 | B3: Rafael | C3: Module | D3: Introduction and Certification Overview | E3: es-a1-module-introduction-and-certification-overview | F3: FALSE | G3: https://github.com/freeCodeCamp/freeCodeCamp/pull/62424
B4: Merged 🎉 | C4: Learn | D4: Certification Introduction | E4: es-a1-learn-certification-introduction | F4: TRUE
B5: 1 | C5: Chapter | D5: Spanish Fundamentals | E5: es-a1-chapter-spanish-fundamentals | F5: FALSE
A6: 45954 | B6: Estefania | C6: Module | D6: Letters, Sounds and First Numbers | E6: es-a1-module-letters-sounds-and-first-numbers | F6: FALSE | G6: https://github.com/freeCodeCamp/freeCodeCamp/pull/62719 rename
B7: Merged 🎉 | C7: Learn | D7: Vowels | E7: es-a1-learn-vowels | F7: TRUE
B8: Merged 🎉 | C8: Learn | D8: Consonants and Special Characters | E8: es-a1-learn-consonants-and-special-characters | F8: TRUE
B9: Merged 🎉 | C9: Practice | D9: The Spanish Alphabet Practice | E9: es-a1-practice-the-alphabet | F9: TRUE
B10: Merged 🎉 | C10: Learn | D10: The First Ten Numbers | E10: es-a1-learn-the-first-ten-numbers | F10: TRUE | G10: https://github.com/freeCodeCamp/freeCodeCamp/pull/64018
B11: Merged 🎉 | C11: Practice | D11: The First Ten Numbers Practice | E11: es-a1-practice-the-first-ten-numbers | F11: TRUE
B12: Merged 🎉 | C12: Review | D12: Spanish Fundamentals Review | E12: es-a1-review-spanish-fundamentals | F12: TRUE
B13: Merged 🎉 | C13: Quiz | D13: Spanish Fundamentals Quiz | E13: es-a1-quiz-spanish-fundamentals | F13: TRUE
B14: 2 | C14: Chapter | D14: Greetings and Introductions | E14: es-a1-chapter-greetings-and-introductions | F14: FALSE
A15: 45940 | B15: Nielda | C15: Module | D15: Greetings and Farewells | E15: es-a1-module-greetings-and-farewells | F15: FALSE | G15: https://github.com/freeCodeCamp/freeCodeCamp/pull/62201
B16: Merged 🎉 | C16: Warm-up | D16: Greetings and Farewells Basics | E16: es-a1-warm-up-greetings-and-farewells-basics | F16: TRUE
B17: Merged 🎉 | C17: Learn | D17: Greetings During the Day | E17: es-a1-learn-greetings-during-the-day | F17: TRUE
B18: Merged 🎉 | C18: Practice | D18: Greetings and Farewells Practice | E18: es-a1-practice-greetings-and-farewells | F18: TRUE
B19: Merged 🎉 | C19: Review | D19: Greetings and Farewells Review | E19: es-a1-review-greetings-and-farewells | F19: TRUE
B20: Merged 🎉 | C20: Quiz | D20: Greetings and Farewells Quiz | E20: es-a1-quiz-greetings-and-farewells | F20: TRUE
A21: 45943 | B21: Rafael | C21: Module | D21: Introducing Yourself | E21: es-a1-module-introducing-yourself | F21: FALSE | G21: https://github.com/freeCodeCamp/freeCodeCamp/pull/64535
B22: Merged 🎉 | C22: Warm-up | D22: Introducing Yourself Basics | E22: es-a1-warm-up-introducing-yourself-basics | F22: TRUE | G22: https://github.com/freeCodeCamp/freeCodeCamp/pull/62465
B23: Merged 🎉 | C23: Learn | D23: Meet Luna | E23: es-a1-learn-meet-luna | F23: TRUE | G23: https://github.com/freeCodeCamp/freeCodeCamp/pull/63825
B24: Merged 🎉 | C24: Learn | D24: Meet Mateo | E24: es-a1-learn-meet-mateo | F24: TRUE
B25: Merged 🎉 | C25: Learn | D25: Meet Julieta | E25: es-a1-learn-meet-julieta | F25: TRUE
B26: Merged 🎉 | C26: Practice | D26: Introducing Yourself Practice | E26: es-a1-practice-introducing-yourself | F26: TRUE | G26: https://github.com/freeCodeCamp/freeCodeCamp/pull/63985
B27: Merged 🎉 | C27: Review | D27: Introducing Yourself Review | E27: es-a1-review-introducing-yourself | F27: TRUE
B28: Merged 🎉 | C28: Quiz | D28: Introducing Yourself Quiz | E28: es-a1-quiz-introducing-yourself | F28: TRUE
B29: Estefania | C29: Module | D29: First Questions | E29: es-a1-module-first-questions | F29: FALSE | G29: https://github.com/freeCodeCamp/freeCodeCamp/pull/63672
B30: Merged 🎉 | C30: Warm-up | D30: First Questions Basics | E30: es-a1-warm-up-first-questions-basics | F30: TRUE
B31: Merged 🎉 | C31: Learn | D31: Meet Angela and Basti | E31: es-a1-learn-meet-angela-and-basti | F31: TRUE
B32: Merged 🎉 | C32: Practice | D32: First Questions Practice | E32: es-a1-practice-first-questions | F32: TRUE
B33: Merged 🎉 | C33: Review | D33: First Questions Review | E33: es-a1-review-first-questions | F33: TRUE
B34: Merged 🎉 | C34: Quiz | D34: First Questions Quiz | E34: es-a1-quiz-first-questions | F34: TRUE
B35: 3 | C35: Chapter | D35: Basic Personal Details | E35: es-a1-chapter-basic-personal-details | F35: FALSE
B36: Estefania | C36: Module | D36: Numbers 10 to 29 | E36: es-a1-module-numbers-10-to-29 | F36: FALSE | G36: https://github.com/freeCodeCamp/freeCodeCamp/pull/64080
B37: Merged 🎉 | C37: Warm-up | D37: Remember First Numbers | E37: es-a1-warm-up-remember-first-numbers | F37: TRUE
B38: Merged 🎉 | C38: Learn | D38: Numbers 10 to 29 | E38: es-a1-learn-numbers-10-to-29 | F38: TRUE
B39: Merged 🎉 | C39: Practice | D39: Using Numbers 10 to 29 | E39: es-a1-practice-using-numbers-10-to-29 | F39: TRUE
B40: Merged 🎉 | C40: Review | D40: Numbers 10 to 29 Review | E40: es-a1-review-numbers-10-to-29 | F40: TRUE
...

Sheet Basic Personal Details
A2: Chapter Basic Personal Details Objective
A3: By the end of this chapter, learners will be able to recognize, ask for, and provide personal information (such as name, surname, nationality, age, phone number, and email) using numbers 1–20 and the verbs llamarse, ser, and tener in the first and second person singular.
A4: Module 1 — Numbers from 10 to 29 Module 2 — Sharing Your Personal Details
A5: Module 1 | B5: ='Chapter Status'!D36 -> Numbers 10 to 29
A6: Listening By the end of this module, learners will be able to recognize numbers from 10 to 29 when spoken slowly in isolation or short sequences. By the end of this module, learners will be able to complete a listening task in which they write numbers in the order they hear them. Reading By the end of this module, learners will be able to match written numbers with their corresponding digits in a multiple-choice or matching exercise.
A7: Plan curricular Module 1
A8: Gramática | C8: Function | D8: Vocabulário Específico | E8: Nociones generales | F8: Nociones específicas
A9: Cardinal numbers 1–20 Review: tengo + number (for age) No new conjugations introduced | C9: Identifying and recognizing numbers Providing numerical information (age, phone digits) in controlled tasks Completing simple forms requiring numerical data | D9: números 0 to 29 | E9: Cantidad numérica: números cardinales Edad: número cardinal + “años” (input only) | F9: Datos personales: edad Datos personales: número de teléfono
A10: Tácticas y estrategias pragmáticas | C10: Géneros discursivos y productos textuales | D10: Ortografía | E10: Pronunciación y prosodia | F10: Cultura, saberes y comportamientos
A11: (None required — numbers are literal; no pragmatic strategies needed.) | C11: Formularios muy simples (personal data forms) Listas (numbers in order) | D11: Teach explicitly: Hyphen removal in compound numbers (dieciséis, diecisiete, etc.) Accent marks: dieciséis Lowercase number words in Spanish | E11: Teach explicitly: Stress patterns in numbers: diece-SÉIS, diecio-CHO Clear articulation of /s/ vs. /z/ depending on variety (neutral Latin American)
A12: Block type | B12: Block name | C12: Base Material | D12: Content planning | E12: Instructions/ notes
A13: ='Chapter Status'!C16 -> Warm-up | B13: ='Chapter Status'!D37 -> Remember First Numbers | C13: ES_A1_numbers-0-100 Review first numbers 0 to 9 Introduce other content if you judge necessary | E13: Objective is to review the first numbers to give a nice structure for the following blocks.
A14: ='Chapter Status'!C17 -> Learn | B14: ='Chapter Status'!D38 -> Numbers 10 to 29 | C14: Numbers 11 to 20 and any other audio you think is necessary ES_A1_numbers-0-100 numbers 10 to 29 | E14: Objectives: Recognize 11–20 when heard slowly Match written numbers to digits Identify 11–20 in simple tasks Content: Teach numbers 11–20 once, doce, trece, catorce, quince, dieciséis, diecisiete, dieciocho, diecinueve, veinte Highlight spelling patterns (Mention veintiún) Highlight accents where needed Orthographic point: dieciséis (accent)
A15: ='Chapter Status'!C18 -> Practice | B15: ='Chapter Status'!D39 -> Using Numbers 10 to 29 | C15: Numbers 1 to 20 and any other audio you think is necessary ES_A1_numbers-0-100 uno, dos, tres, cuatro, cinco, seis, siete, ocho, nueve, diez, once, doce, trece, catorce, quince, dieciséis, diecisiete, dieciocho, diecinueve, veinte | E15: Objectives: Consolidate recognition of 1–20 Write numbers correctly after listening Match, order, and identify numbers in various tasks Activities may include for example number ordering for example: Listening sequence: “Escribe el número según el orden en que lo escuchas.” Completing simple numeric fields (edad, número) No sentences longer than 2–3 words. Avoid introducing age grammar here.
A16: ='Chapter Status'!C19 -> Review | B16: ='Chapter Status'!D40 -> Numbers 10 to 29 Review | C16: Grammar Highlights Glossary | E16: Grammar Cardinal numbers 1–20 Accented forms: dieciséis No additional grammar Glossary Full list of numbers 1–20 in order Additional small glossary if necessary
A17: ='Chapter Status'!C20 -> Quiz | B17: ='Chapter Status'!D41 -> Numbers 10 to 29 Quiz | C17: Module Quiz | E17: The quiz block script requires either 10 or 20 questions. To pass, learners must score at least 90%. By default, our placeholder quiz block has 10 questions, but you can change it to 20 if you prefer.
A21: Module 2 - Sharing Your Personal Details
A22: Listening By the end of this module, learners will be able to recognize second-person questions about personal information (e.g., tu apellido, tu número, tu correo) when spoken slowly in short exchanges. By the end of this module, learners will be able to identify the personal information being requested in simple listening tasks (name, surname, nationality, age, phone number, email). Reading By the end of this module, learners will be able to match second-person prompts (e.g., tu nombre, tu nacionalidad) with the correct information fields on a simple personal data form. By the end of this module, learners will be able to understand short written prompts about personal data and choose correct first-person answers. Writing By the end of this module, learners will be able to complete a simple personal information form using first-person expressions (Me llamo…, Soy…, Tengo…, Mi correo es…, Mi número es…)
A23: Plan curricular Module 2
A24: Gramática | C24: Function | D24: Vocabulário Específico | E24: Nociones generales | F24: Nociones específicas
A25: 1. Second-person singular forms te llamas eres tienes (Chapter 2 showed these only inside questions; Module 2 teaches them as active forms learners can recognize and respond to.) 2. Possessive adjectives (essential for forms) mi tu 3. Email and number structures Mi número es… Mi correo es… Review only (NOT taught again) me llamo soy tengo Not included yet Él / Ella saved for Chapter 4 Su / sus saved for Chapter 4 | C25: Asking for personal information using tú. Giving personal information using yo. Completing personal data forms. Providing phone numbers and email addresses in simple formats. | D25: Key Vocabulary (Personal Data) Identity: nombre, apellido Age: edad Nationality & Country: nacionalidad, país, ciudad Profession: profesión Contact Info: correo electrónico, número de teléfono, móvil Other Data Words: formulario, datos personales Professions used in forms and profiles according to the monologues / dialogues: Contact terms: arroba (@), punto (.), número questions: Cuál | E25: dentidad personal (nombre, apellido) Datos de contacto (número, correo) Origen (nacionalidad, país) Edad (número + años) | F25: Datos personales nombre Datos personales apellido Datos personales nacionalidad Datos personales edad Datos personales profesión Datos personales correo, número
A26: Tácticas y estrategias pragmáticas | C26: Géneros discursivos y productos textuales | D26: Ortografía | E26: Pronunciación y prosodia | F26: Cultura, saberes y comportamientos
A27: Asking for clarification: ¿Tu apellido? ¿Tu número? Ellipsis: omitting tú in everyday questions ¿Cómo te llamas? (instead of ¿Cómo tú te llamas?) Confirming details: ¿Tu correo es…? | C27: Personal data forms (formularios) Brief personal profiles (profiles for HR) Mini onboarding dialogues | D27: Teach explicitly: (Review) Capitalization of names, surnames, countries, nationalities Accent marks: teléfono, número, país Email writing conventions: arroba, punto Review Gender adjustments for nationalities (colombiano/colombiana) | E27: Rhythm of phone numbers (pausing after 2–3 digits) Pronunciation of email components | F27: Personal data conventions in Latin America Optional: two-surname system (input only)
A28: Block type | B28: Block name | C28: Base Material | D28: Content planning | E28: Instructions/ notes
A29: ='Chapter Status'!C22 -> Warm-up | B29: ='Chapter Status'!D43 -> Getting Ready to Share Personal Details | C29: One audio with the alphabet suggested: ES_A1_alphabet.mp3 ES_A1_numbers-0-9 ES_A1_personal-details-vocabulary Nombre, apellido, Primer apellido, Segundo apellido, apodo, Nacionalidad, Profesión, Correo electrónico, Número de teléfono | D29: Write your planning for this block here. Check the the Curricular plan below to check what's expected from this module. Do the same to the following rows | E29: Activate prior knowledge from Chapter 1 (alphabet) and Module 1 (numbers 1–10). Present a short vocabulary list with personal data terms that will appear in the Learn blocks. Do not introduce new grammar. Keep exposure brief and focused.
A30: ='Chapter Status'!C23 -> Learn | B30: ='Chapter Status'!D44 -> Basic Personal Information | C30: ES_A1_esteban-personal-records-dialogue-with-angela Intro (Not to record) Esteban visits the Human Resources office at Andes Commerce to update his personal information for the company records. Ángela, the HR representative, asks him basic questions to complete the form. Dialogue (to record) Ángela: Hola, buenas tardes. Gracias por venir. ¿Cuál es tu nombre y apellido? Esteban: Me llamo Esteban Navarro Huamán. Ángela: ¿Navarro con dos erres? Esteban: Sí, con dos erres. Ángela: ¿Y Huamán? ¿Cómo se escribe? Esteban: H-U-A-M-A-N, con acento en la última a. Ángela: Perfecto. Entonces, Esteban Navarro Huamán. ¿Cuál es tu nacionalidad? Esteban: Soy peruano. Ángela: Ah, de Perú. Muy bien. ¿Y tu profesión? Esteban: Soy desarrollador web. Ángela: Gracias, Esteban. Todo listo por hoy. Esteban: Gracias, Ángela. Hasta luego. ES_A1_mateo-email-dialogue-with-camila Camila: Hola, Mateo. ¿Cuál es tu correo electrónico? Mateo: Mi correo es mateo.delgado@sanjuan.pr. ¿Quieres que te lo deletree? Camila: Sí, por favor. Mateo: Es m - a - t - e - o punto d - e - l - g - a - d - o arroba s - a - n - j - u - a - n punto p - r. Camila: ¿sanjuan.pr? Mateo: Sí, correcto. Camila: Perfecto. Muchas gracias. Mateo: ¡De nada! | D30: Description: --Esteban visits the Human Resources office at Andes Commerce to update his personal information for the company records. Ángela, the HR representative, asks him basic questions to complete the form.-- | E30: Dialogue ES_A1_esteban-angela-update-personal-records is perfect to introduce vocab numbre and apellido, review alphabet (chapter 1), content from chapter 2 and some particular cases as double erres. If a sentence is new (like todo listo por hoy) make sure to teach it. Make sure to explain questions starting with Cuál, and similar questions where Cuál is omited but the meaning is there. You chould also teach the word "Como". Make sure to teach key vocab related to email and phone numbers as "te lo deletree" and so on. ES_A1_contact-info-dialogue-camila-mateo is perfect to reinforce spelling while introducing numbers, and sentences to confirm information. Take your time with these number tasks. Grammar wise, remember that this module introduces much of the conjugation of Tú, while review Yo. But the main focus is second person. This block has to be planned alongside the following learn block
A31: Learn | B31: ='Chapter Status'!D45 -> Contact Information and Spelling | C31: ES_A1_mateo-camila-phone-number-dialogue Mateo: Hola, Camila. ¿Cuál es tu número de teléfono? Camila: Mi número es +57 313 445 9280. Mateo: ¿Puedes repetirlo? Camila: Claro, es +57 313 445 9280. Mateo: Gracias. Camila: ¿Y el tuyo, Mateo? Mateo: Es 213 554 0028. Camila: ¿Otra vez, por favor? Mateo: 213 554 0028. ES_A1_basti-personal-details Intro (not to record) Basti is on a call confirming his personal details. In this audio you listen to his side of the conversation. To record Hola, buenas noches. Me llamo Sebastián Ávila Gómez. Sebastián se escribe s-e-b-a-s-t-i-á-n, con acento en la última a. ¿Puedo usar mi apodo? Mi apodo es Basti. Se escribe B-a-s-t-i. Sí, Gómez termina en z. Soy guatemalteco y soy analista junior. Mi correo completo es basti.ag@quetzal.gt El usuario es b-a-s-t-i punto a-g. El dominio es q-u-e-t-z-a-l punto g-t. Y mi número es +502 4489 2201. Sí, correcto. Gracias. | E31: ES_A1_basti-personal-details continues from the previous learn block, I've only separated it to avoid making the first learn block too long. make sure to plan this together with the previous block.
A32: ='Chapter Status'!C26 -> Practice | B32: ='Chapter Status'!D46 -> Personal Details in Action | C32: ES_A1_personal-details-just-questions ¿Cuál es tu nombre?; ¿Cuál es tu apellido?; ¿Cuál es tu primer apellido?; ¿Cuál es tu segundo apellido?; ¿Cuál es tu nombre y apellido?; ¿Cuál es tu apodo?; ¿Cuál es tu nacionalidad?; ¿Cuál es tu profesion?; ¿Cuál es tu número de teléfono?; ¿Cuál es tu correo electrónico? ¿Cómo se escribe? ¿Cómo te llamas? ¿Cómo se deletrea? ¿Quieres que te lo deletree? ¿ Puedes repetirlo, por favor?, ¿ Puedes repetirlo? ¿Otra vez, por favor? ES_A1_all-special-characters ES_A1_julieta-personal-details Intro (not to record) Julieta is in a call confirming his personal details. In this audio you listen to her side of the conversation. To record Hola, sí, buenos días. Me llamo Julieta Cáceres López. Cáceres lleva acento en la primera a. López también tiene acento en la o , y termina en z. Mi correo es julieta.caceres@andes.com. Repito: j-u-l-i-e-t-a punto c-a-c-e-r-e-s arroba a-n-d-e-s punto com. Sí, correcto. Soy uruguaya y soy estratega de marketing. Y mi número es +598 94 227 495. Sí, ese mismo. De acuerdo, perfecto. Muchas gracias. Hasta luego. Reading practice Formulario de datos personales ES_A1_luna-personal-data-form Nombre: Luna Primer apellido: Méndez Segundo apellido: Pérez Nacionalidad: chilena Profesión: científica de datos Correo electrónico: luna.mendez@andes.com Número de teléfono: +56 923 881 240 Edad: 25 | E32: I wasn't sure how you two would like to proceed with the practice block, so I've prepared some audio with questions. A text from Julieta using the same structure as Basti and a profile form from Luna. Feel free to explore how you can use these in practice. For example, you could combine ES_A1_luna-personal-data-form text wit some questions from ES_A1_personal-details-just-questions, and ask learner to find the information the audio is asking on the form. There are endless possibilities here. =)
A33: ='Chapter Status'!C27 -> Review | B33: ='Chapter Status'!D47 -> Sharing Your Personal Details Review | C33: Grammar Highlights Glossary
A34: ='Chapter Status'!C28 -> Quiz | B34: ='Chapter Status'!D48 -> Sharing Your Personal Details Quiz | C34: Module Quiz | E34: The quiz block script requires either 10 or 20 questions. To pass, learners must score at least 90%. By default, our placeholder quiz block has 10 questions, but you can change it to 20 if you prefer.

Sheet Spanish Fundamentals
A2: Chapter Spanish Fundamentals Objective
A3: By the end of this Chapter, learners will be able to identify and differentiate spanish Alphabet letters
A4: List the modules inside the chapter here
A5: Module 1 The alphabet, accents, and punctuation
A6: - Vowels: By the end of this module learners will be able to identify the five vowels in spanish and differentiate their sounds. - Consonants: By the end of this module learners will be able to identify the consonants and differentiate their sounds. - Consonants: By the end of the module, learners will be able to type special ñ - Punctuation: By the end of this module, learners will be able to correctly type the opening of signo de interrogación and signo de exclamación ¿? ¡!
A7: Plan curricular Module 1
A8: Gramática | C8: Function | D8: Vocabulário Específico | E8: Nociones generales | F8: Nociones específicas
A9: List of grammar to focus on this lesson | C9: list of functions to be covered | D9: List of specific vocab | E9: List here the general field you are teaching based on the reference material | F9: List here the specific notions you are teaching based on the reference material
A10: Tácticas y estrategias pragmáticas | C10: Géneros discursivos y productos textuales | D10: Ortografía | E10: Pronunciación y prosodia | F10: Cultura, saberes y comportamientos
A11: If you are not covering this topic leave it empty | C11: If you are teaching writing you should pay extra attentio to this section. If you are not covering this topic leave it empty | D11: If you are teaching ortography list it here. If not leave it empty | E11: If you are teaching pronunciation list it here. If not leave it empty | F11: If you are not covering this topic leave it empty
A12: Block type | B12: Block name | C12: Base Material | D12: Content planning | E12: Instructions/ notes
A13: ='Chapter Status'!C7 -> Learn | B13: ='Chapter Status'!D7 -> Vowels | D13: Write your planning for this block here. Check the the Curricular plan below to check what's expected from this module. Do the same to the following rows | E13: Make sure you have audio needed on the CDN (Or that you'll record them)
A14: ='Chapter Status'!C8 -> Learn | B14: ='Chapter Status'!D8 -> Consonants and Special Characters | C14: There can be more than one Learn block. It will depend on how long and complex is your base material. Paste the base material (dialogue or monologue) to be covered in this learning section | E14: Make sure you have audio needed on the CDN (Or that you'll record them)
A15: Learn | B15: ='Chapter Status'!D10 -> The First Ten Numbers | C15: Numbers 0 to 10 and any other audio you think is necessary ES_A1_numbers-0-100 zero, uno, dos, tres, cuatro, cinco, seis, siete, ocho, nueve, diez | D15: Write your planning for this block here. Check the the Curricular plan below to check what's expected from this module. Do the same to the following rows | E15: Objectives: Recognize 1–10 when heard slowly Match written numbers to digits Identify numbers Content: Teach numbers 1–10 individually uno, dos, tres, cuatro, cinco, seis, siete, ocho, nueve, diez Each number is taught with: written form digit form a simple example sentence (optional, single-word preferred) No inflection, no gender No verb instruction
A16: Learn | B16: ='Chapter Status'!D11 -> The First Ten Numbers Practice
A17: ='Chapter Status'!C12 -> Review | B17: ='Chapter Status'!D12 -> Spanish Fundamentals Review | C17: Grammar Highlights Glossary
A18: ='Chapter Status'!C13 -> Quiz | B18: ='Chapter Status'!D13 -> Spanish Fundamentals Quiz | C18: Module Quiz | E18: The quiz block script requires either 10 or 20 questions. To pass, learners must score at least 90%. By default, our placeholder quiz block has 10 questions, but you can change it to 20 if you prefer.

Sheet Greetings and Introductions
A2: Chapter Greetings and Introductions Objective
A3: By the end of this Chapter, learners will be able to greet others, introduce themselves, and exchange basic personal information (such as name, nationality, and where they are from) using simple expressions in Spanish.
A4: Module 1: Greetings and farewells (Hola, buenos días, adiós…) Module 2: Introducing yourself (Me llamo…, Soy de…, Tengo … años) Module 3: Asking and giving basic personal information (¿Cómo te llamas?, ¿De dónde eres?, ¿Qué haces?)
A5: Module 1 Greetings and Farewells
A6: "By the end of this module, learners will be able to greet others, introduce themselves with name and profession, and say goodbye using simple expressions in Spanish. Listening By the end of the module, learners will be able to identify common greetings, introductions (Me llamo… / Soy…), and farewells when spoken slowly in short monologues. Reading By the end of the module, learners will be able to match 5 greetings and farewells with their English meanings in a multiple-choice or matching exercise. Writing By the end of the module, learners will be able to complete a short self-introduction text (monologue) with missing words, choosing correctly from a provided word list (including distractors)."
A7: Plan curricular Module 1
A8: Gramática | C8: Function | D8: Vocabulário Específico | E8: Nociones generales | F8: Nociones específicas
A9: "Grammar to cover explicitly in Module 1 Names without article: Soy Elena. Me llamo Camila. Time of day nouns (greetings): Buenos días. Buenas tardes. Buenas noches. Verb ser (present, 1st person singular): Soy Camila. Soy analista. Simple affirmative sentences: Me llamo Esteban. Soy diseñadora. Grammar present but not taught yet (exposure only) Gender of nouns (-o / -a): diseñador / diseñadora Use and omission of the article: Soy diseñadora Subject pronouns and omission: Soy Elena (without yo)" | C9: "Identificar Dar información (datos personales: nombre, profesión) Expresar certeza (con enunciados declarativos)" | D9: Diseñadora, analista, desarrollador | E9: "Cualidad general: ser - Soy Camila. Soy analista. Referencias generales de nociones temporales: día, tarde, noche, mañana, pronto" | F9: "Datos personales: Nombre (nombre, apellido, llamarse) Datos personales: Profesión (Soy analista, Soy diseñadora, Soy desarrollador) Profesiones y cargos (basic jobs)"
A10: Tácticas y estrategias pragmáticas | C10: Géneros discursivos y productos textuales | D10: Ortografía | E10: Pronunciación y prosodia | F10: Cultura, saberes y comportamientos
A11: Mantenimiento del referente e hilo discursivo: Sustitución por Ø (subject ellipsis in Soy Elena instead of Yo soy Elena) | C11: Notas muy breves y sencillas (escritas) | D11: Teach explicitly: Capitalization at the beginning of sentences. Capitalization of names. Expose only: Accent marks (días, adiós). ll in llamo. | E11: Not covered | F11: not covered
A12: Block type | B12: Block name | C12: Base Material | D12: Content planning | E12: Instructions/ notes
A13: ='Chapter Status'!C16 -> Warm-up | B13: ='Chapter Status'!D16 -> Greetings and Farewells Basics | C13: Greetings Hola – Hello Buenos días – Good morning Buenas tardes – Good afternoon Buenas noches – Good evening / Good night Introductions Me llamo… – My name is… Soy… – I am… Professions diseñadora, analista, desarrollador Farewells Adiós – Goodbye chao – Bye Hasta luego – See you later Hasta mañana – See you tomorrow Hasta pronto – See you soon | D13: Write your planning for this block here. Check the the Curricular plan below to check what's expected from this module | E13: Make sure you have audio needed on the CDN (Or that you'll record them)
A14: ='Chapter Status'!C17 -> Learn | B14: ='Chapter Status'!D17 -> Greetings During the Day | C14: Lesson 1 Monologues with Professions Monologue 1 Morning Hola, buenos días. Me llamo Elena. Soy diseñadora. Hasta luego. Adiós. Monologue 2 Afternoon Hola, buenas tardes. Soy Camila. Soy analista. Adiós. Hasta pronto. Monologue 3 Night Hola, buenas noches. Me llamo Esteban. Soy desarrollador. Hasta mañana. Chao. | D14: Write your planning for this block here. Check the the Curricular plan below to check what's expected from this module | E14: Make sure you have audio needed on the CDN (Or that you'll record them)
A15: ='Chapter Status'!C18 -> Practice | B15: ='Chapter Status'!D18 -> Greetings and Farewells Practice | C15: All 3 monologues and Writing Practice Camila is introducing herself at work in the afternoon. Complete her introduction with the correct words. ___, buenas ___. ___ Camila. ___ analista. Hasta ___, ___. Word options (with distractors) : Hola – Me llamo – Soy – Adiós – luego – mañana – noches – pronto Correct answer: Writing practice 1 Hola, buenas tardes. Me llamo Camila. Soy analista. Hasta luego, Adiós. | D15: Write your planning for this block here. Check the the Curricular plan below to check what's expected from this module | E15: Make sure to also include speaking tasks even if we still don't have them available.
A16: ='Chapter Status'!C19 -> Review | B16: ='Chapter Status'!D19 -> Greetings and Farewells Review | C16: Grammar Highlights Glossary | D16: Write your planning for this block here. Check the the Curricular plan below to check what's expected from this module
A17: ='Chapter Status'!C20 -> Quiz | B17: ='Chapter Status'!D20 -> Greetings and Farewells Quiz | C17: Module Quiz | D17: Write your planning for this block here. Check the the Curricular plan below to check what's expected from this module | E17: The quiz block script requires either 10 or 20 questions. To pass, learners must score at least 90%. By default, our placeholder quiz block has 10 questions, but you can change it to 20 if you prefer.
A21: Module 2 – Introducing Yourself Objectives RAFAEL
A22: "Main Objective By the end of this module, learners will be able to introduce themselves with name, profession, nationality, and age using simple expressions in Spanish. Listening By the end of the Module, learners will be able to identify introductions that include name, profession, nationality, and age when spoken slowly in short monologues. Reading By the end of the module, learners will be able to match written sentences of self-introduction (name, profession, nationality, age) with their English meanings in a multiple-choice or matching exercise. Writing By the end of the module, learners will be able to complete a short self-introduction text (monologue) with missing words (name, profession, nationality, age) by selecting the correct items from a word list (including distractors)."
A23: Plan curricular Module 2 - Rafael
A24: Gramática | C24: Function | D24: Vocabulário Específico | E24: Nociones generales | F24: Nociones específicas
A25: Grammar to cover explicitly ser with profession and nationality. tener with numbers to express age. Simple affirmative sentences (SVO order). Subject–attribute agreement (chileno/chilena, uruguayo/uruguaya). Numbers (cardinals for age). Grammar present but not taught yet (exposure only) Género en nacionalidades (chileno/chilena, puertorriqueño/puertorriqueña) Plural de años (Tengo 28 años → plural not explained) | C25: Identificar: nombre, profesión, nacionalidad Dar información: datos personales (edad, nacionalidad) Expresar certeza: enunciados declarativos | D25: Científica de datos – Data Scientist Ingeniero de software – Software Engineer Estratega de marketing – Marketing Strategist | E25: Profesion: ser + profesion Example: Soy Ingeniero de Software. Soy cientifica de datos. Origen: ser + nacionalidad Example: Soy chilena. Soy uruguaya. Edad, vejez: tener + número cardinal ~ años Example: Tengo 28 años. Cantidad numérica: números cardinales Example: veinticinco, treinta, treinta y seis | F25: Datos personales: nombre Datos personales: profesión Datos personales: nacionalidad Datos personales: edad
A26: Tácticas y estrategias pragmáticas | C26: Géneros discursivos y productos textuales | D26: Ortografía | E26: Pronunciación y prosodia | F26: Cultura, saberes y comportamientos
A27: Mantenimiento del referente e hilo discursivo: Sustitución por Ø (Soy chilena instead of Yo soy chilena) | C27: Conversaciones cara a cara, muy breves e informales, sobre personas (adapted here as short monologues of self-introduction) | D27: Ortografía to cover explicitly in Module 2 Mayúscula en nombres y nacionalidades (Luna, Chilena, Uruguaya, Puertorriqueño) Uso de tilde en palabras comunes (años, científica, puertorriqueño) | E27: Not covered | F27: Not covered
A28: Block type | B28: Block name | C28: Base Material | D28: Content planning | E28: Instructions
A29: ='Chapter Status'!C22 -> Warm-up | B29: ='Chapter Status'!D22 -> Introducing Yourself Basics | C29: Professions Científica de datos Ingeniero de software Estratega de marketing Nationalities chilena puertorriqueño uruguaya Numbers (for age) veinte – twenty veinticinco – twenty-five veintiocho – twenty-eight treinta – thirty treinta y seis – thirty-six | D29: Warm-up (multiple choice tasks) Profession - Científica de datos - Ingeniero de software - Estratega de marketing Nationality - Chilena - Puertorriqueño - Uruguaya Number (age) - 28 años - 25 años - 36 años
